INFO:aiogram.dispatcher.dispatcher:Stop polling...
ERROR:asyncio:Unclosed client session
client_session: <aiohttp.client.ClientSession object at 0x7fc393e150f0>
INFO:aiogram.dispatcher.dispatcher:Start polling.
INFO:root:{"message_id": 11, "from": {"id": 1211431388, "is_bot": false, "first_name": "Иван", "last_name": "Книженцев", "username": "IKnigencev", "language_code": "ru"}, "chat": {"id": 1211431388, "first_name": "Иван", "last_name": "Книженцев", "username": "IKnigencev", "type": "private"}, "date": 1675102885, "text": "/start", "entities": [{"type": "bot_command", "offset": 0, "length": 6}]}
WARNING:aiogram.dispatcher.dispatcher:Polling is stopped.
INFO:aiogram.dispatcher.dispatcher:Stop polling...
ERROR:asyncio:Unclosed client session
client_session: <aiohttp.client.ClientSession object at 0x7f1f71611d80>
INFO:aiogram.dispatcher.dispatcher:Start polling.
ERROR:asyncio:Task exception was never retrieved
future: <Task finished name='Task-8' coro=<Dispatcher._process_polling_updates() done, defined at /home/ivan/past_dev/Project/Telegram_bot/telegram_finance/venv/lib64/python3.10/site-packages/aiogram/dispatcher/dispatcher.py:407> exception=TypeError('Model.create() takes 1 positional argument but 4 were given')>
Traceback (most recent call last):
  File "/home/ivan/past_dev/Project/Telegram_bot/telegram_finance/venv/lib64/python3.10/site-packages/aiogram/dispatcher/dispatcher.py", line 415, in _process_polling_updates
    for responses in itertools.chain.from_iterable(await self.process_updates(updates, fast)):
  File "/home/ivan/past_dev/Project/Telegram_bot/telegram_finance/venv/lib64/python3.10/site-packages/aiogram/dispatcher/dispatcher.py", line 235, in process_updates
    return await asyncio.gather(*tasks)
  File "/home/ivan/past_dev/Project/Telegram_bot/telegram_finance/venv/lib64/python3.10/site-packages/aiogram/dispatcher/handler.py", line 117, in notify
    response = await handler_obj.handler(*args, **partial_data)
  File "/home/ivan/past_dev/Project/Telegram_bot/telegram_finance/venv/lib64/python3.10/site-packages/aiogram/dispatcher/dispatcher.py", line 256, in process_update
    return await self.message_handlers.notify(update.message)
  File "/home/ivan/past_dev/Project/Telegram_bot/telegram_finance/venv/lib64/python3.10/site-packages/aiogram/dispatcher/handler.py", line 117, in notify
    response = await handler_obj.handler(*args, **partial_data)
  File "/home/ivan/past_dev/Project/Telegram_bot/telegram_finance/server.py", line 18, in cmd_start
    User.create(*get_user_data(message["from"]))
TypeError: Model.create() takes 1 positional argument but 4 were given
ERROR:asyncio:Task exception was never retrieved
future: <Task finished name='Task-113' coro=<Dispatcher._process_polling_updates() done, defined at /home/ivan/past_dev/Project/Telegram_bot/telegram_finance/venv/lib64/python3.10/site-packages/aiogram/dispatcher/dispatcher.py:407> exception=TypeError('Model.create() takes 1 positional argument but 4 were given')>
Traceback (most recent call last):
  File "/home/ivan/past_dev/Project/Telegram_bot/telegram_finance/venv/lib64/python3.10/site-packages/aiogram/dispatcher/dispatcher.py", line 415, in _process_polling_updates
    for responses in itertools.chain.from_iterable(await self.process_updates(updates, fast)):
  File "/home/ivan/past_dev/Project/Telegram_bot/telegram_finance/venv/lib64/python3.10/site-packages/aiogram/dispatcher/dispatcher.py", line 235, in process_updates
    return await asyncio.gather(*tasks)
  File "/home/ivan/past_dev/Project/Telegram_bot/telegram_finance/venv/lib64/python3.10/site-packages/aiogram/dispatcher/handler.py", line 117, in notify
    response = await handler_obj.handler(*args, **partial_data)
  File "/home/ivan/past_dev/Project/Telegram_bot/telegram_finance/venv/lib64/python3.10/site-packages/aiogram/dispatcher/dispatcher.py", line 256, in process_update
    return await self.message_handlers.notify(update.message)
  File "/home/ivan/past_dev/Project/Telegram_bot/telegram_finance/venv/lib64/python3.10/site-packages/aiogram/dispatcher/handler.py", line 117, in notify
    response = await handler_obj.handler(*args, **partial_data)
  File "/home/ivan/past_dev/Project/Telegram_bot/telegram_finance/server.py", line 18, in cmd_start
    data = get_user_data(message["from"])
TypeError: Model.create() takes 1 positional argument but 4 were given
ERROR:asyncio:Task exception was never retrieved
future: <Task finished name='Task-210' coro=<Dispatcher._process_polling_updates() done, defined at /home/ivan/past_dev/Project/Telegram_bot/telegram_finance/venv/lib64/python3.10/site-packages/aiogram/dispatcher/dispatcher.py:407> exception=TypeError('Model.create() takes 1 positional argument but 4 were given')>
Traceback (most recent call last):
  File "/home/ivan/past_dev/Project/Telegram_bot/telegram_finance/venv/lib64/python3.10/site-packages/aiogram/dispatcher/dispatcher.py", line 415, in _process_polling_updates
    for responses in itertools.chain.from_iterable(await self.process_updates(updates, fast)):
  File "/home/ivan/past_dev/Project/Telegram_bot/telegram_finance/venv/lib64/python3.10/site-packages/aiogram/dispatcher/dispatcher.py", line 235, in process_updates
    return await asyncio.gather(*tasks)
  File "/home/ivan/past_dev/Project/Telegram_bot/telegram_finance/venv/lib64/python3.10/site-packages/aiogram/dispatcher/handler.py", line 117, in notify
    response = await handler_obj.handler(*args, **partial_data)
  File "/home/ivan/past_dev/Project/Telegram_bot/telegram_finance/venv/lib64/python3.10/site-packages/aiogram/dispatcher/dispatcher.py", line 256, in process_update
    return await self.message_handlers.notify(update.message)
  File "/home/ivan/past_dev/Project/Telegram_bot/telegram_finance/venv/lib64/python3.10/site-packages/aiogram/dispatcher/handler.py", line 117, in notify
    response = await handler_obj.handler(*args, **partial_data)
  File "/home/ivan/past_dev/Project/Telegram_bot/telegram_finance/server.py", line 18, in cmd_start
    data = get_user_data(message["from"])
TypeError: Model.create() takes 1 positional argument but 4 were given
ERROR:asyncio:Task exception was never retrieved
future: <Task finished name='Task-232' coro=<Dispatcher._process_polling_updates() done, defined at /home/ivan/past_dev/Project/Telegram_bot/telegram_finance/venv/lib64/python3.10/site-packages/aiogram/dispatcher/dispatcher.py:407> exception=TypeError('Model.create() takes 1 positional argument but 4 were given')>
Traceback (most recent call last):
  File "/home/ivan/past_dev/Project/Telegram_bot/telegram_finance/venv/lib64/python3.10/site-packages/aiogram/dispatcher/dispatcher.py", line 415, in _process_polling_updates
    for responses in itertools.chain.from_iterable(await self.process_updates(updates, fast)):
  File "/home/ivan/past_dev/Project/Telegram_bot/telegram_finance/venv/lib64/python3.10/site-packages/aiogram/dispatcher/dispatcher.py", line 235, in process_updates
    return await asyncio.gather(*tasks)
  File "/home/ivan/past_dev/Project/Telegram_bot/telegram_finance/venv/lib64/python3.10/site-packages/aiogram/dispatcher/handler.py", line 117, in notify
    response = await handler_obj.handler(*args, **partial_data)
  File "/home/ivan/past_dev/Project/Telegram_bot/telegram_finance/venv/lib64/python3.10/site-packages/aiogram/dispatcher/dispatcher.py", line 256, in process_update
    return await self.message_handlers.notify(update.message)
  File "/home/ivan/past_dev/Project/Telegram_bot/telegram_finance/venv/lib64/python3.10/site-packages/aiogram/dispatcher/handler.py", line 117, in notify
    response = await handler_obj.handler(*args, **partial_data)
  File "/home/ivan/past_dev/Project/Telegram_bot/telegram_finance/server.py", line 18, in cmd_start
    data = get_user_data(message["from"])
TypeError: Model.create() takes 1 positional argument but 4 were given
ERROR:asyncio:Task exception was never retrieved
future: <Task finished name='Task-258' coro=<Dispatcher._process_polling_updates() done, defined at /home/ivan/past_dev/Project/Telegram_bot/telegram_finance/venv/lib64/python3.10/site-packages/aiogram/dispatcher/dispatcher.py:407> exception=TypeError('Model.create() takes 1 positional argument but 4 were given')>
Traceback (most recent call last):
  File "/home/ivan/past_dev/Project/Telegram_bot/telegram_finance/venv/lib64/python3.10/site-packages/aiogram/dispatcher/dispatcher.py", line 415, in _process_polling_updates
    for responses in itertools.chain.from_iterable(await self.process_updates(updates, fast)):
  File "/home/ivan/past_dev/Project/Telegram_bot/telegram_finance/venv/lib64/python3.10/site-packages/aiogram/dispatcher/dispatcher.py", line 235, in process_updates
    return await asyncio.gather(*tasks)
  File "/home/ivan/past_dev/Project/Telegram_bot/telegram_finance/venv/lib64/python3.10/site-packages/aiogram/dispatcher/handler.py", line 117, in notify
    response = await handler_obj.handler(*args, **partial_data)
  File "/home/ivan/past_dev/Project/Telegram_bot/telegram_finance/venv/lib64/python3.10/site-packages/aiogram/dispatcher/dispatcher.py", line 256, in process_update
    return await self.message_handlers.notify(update.message)
  File "/home/ivan/past_dev/Project/Telegram_bot/telegram_finance/venv/lib64/python3.10/site-packages/aiogram/dispatcher/handler.py", line 117, in notify
    response = await handler_obj.handler(*args, **partial_data)
  File "/home/ivan/past_dev/Project/Telegram_bot/telegram_finance/server.py", line 18, in cmd_start
    data = get_user_data(message["from"])
TypeError: Model.create() takes 1 positional argument but 4 were given
WARNING:aiogram.dispatcher.dispatcher:Polling is stopped.
INFO:aiogram.dispatcher.dispatcher:Stop polling...
ERROR:asyncio:Unclosed client session
client_session: <aiohttp.client.ClientSession object at 0x7fd250cf9c90>
INFO:aiogram.dispatcher.dispatcher:Start polling.
INFO:root:{"message_id": 18, "from": {"id": 1211431388, "is_bot": false, "first_name": "Иван", "last_name": "Книженцев", "username": "IKnigencev", "language_code": "ru"}, "chat": {"id": 1211431388, "first_name": "Иван", "last_name": "Книженцев", "username": "IKnigencev", "type": "private"}, "date": 1675106369, "text": "/start", "entities": [{"type": "bot_command", "offset": 0, "length": 6}]}
ERROR:asyncio:Task exception was never retrieved
future: <Task finished name='Task-6' coro=<Dispatcher._process_polling_updates() done, defined at /home/ivan/past_dev/Project/Telegram_bot/telegram_finance/venv/lib64/python3.10/site-packages/aiogram/dispatcher/dispatcher.py:407> exception=TypeError('Model.create() takes 1 positional argument but 4 were given')>
Traceback (most recent call last):
  File "/home/ivan/past_dev/Project/Telegram_bot/telegram_finance/venv/lib64/python3.10/site-packages/aiogram/dispatcher/dispatcher.py", line 415, in _process_polling_updates
    for responses in itertools.chain.from_iterable(await self.process_updates(updates, fast)):
  File "/home/ivan/past_dev/Project/Telegram_bot/telegram_finance/venv/lib64/python3.10/site-packages/aiogram/dispatcher/dispatcher.py", line 235, in process_updates
    return await asyncio.gather(*tasks)
  File "/home/ivan/past_dev/Project/Telegram_bot/telegram_finance/venv/lib64/python3.10/site-packages/aiogram/dispatcher/handler.py", line 117, in notify
    response = await handler_obj.handler(*args, **partial_data)
  File "/home/ivan/past_dev/Project/Telegram_bot/telegram_finance/venv/lib64/python3.10/site-packages/aiogram/dispatcher/dispatcher.py", line 256, in process_update
    return await self.message_handlers.notify(update.message)
  File "/home/ivan/past_dev/Project/Telegram_bot/telegram_finance/venv/lib64/python3.10/site-packages/aiogram/dispatcher/handler.py", line 117, in notify
    response = await handler_obj.handler(*args, **partial_data)
  File "/home/ivan/past_dev/Project/Telegram_bot/telegram_finance/server.py", line 21, in cmd_start
    User.create(data["id_telegram"], data["name"], data["last_name"])
TypeError: Model.create() takes 1 positional argument but 4 were given
WARNING:aiogram.dispatcher.dispatcher:Polling is stopped.
INFO:aiogram.dispatcher.dispatcher:Stop polling...
ERROR:asyncio:Unclosed client session
client_session: <aiohttp.client.ClientSession object at 0x7f1a5d101d80>
ERROR:asyncio:Unclosed connector
connections: ['[(<aiohttp.client_proto.ResponseHandler object at 0x7f1a5d126260>, 58536.683367501)]']
connector: <aiohttp.connector.TCPConnector object at 0x7f1a5d101c60>
INFO:aiogram.dispatcher.dispatcher:Start polling.
INFO:root:{"message_id": 19, "from": {"id": 1211431388, "is_bot": false, "first_name": "Иван", "last_name": "Книженцев", "username": "IKnigencev", "language_code": "ru"}, "chat": {"id": 1211431388, "first_name": "Иван", "last_name": "Книженцев", "username": "IKnigencev", "type": "private"}, "date": 1675106555, "text": "/start", "entities": [{"type": "bot_command", "offset": 0, "length": 6}]}
ERROR:asyncio:Task exception was never retrieved
future: <Task finished name='Task-6' coro=<Dispatcher._process_polling_updates() done, defined at /home/ivan/past_dev/Project/Telegram_bot/telegram_finance/venv/lib64/python3.10/site-packages/aiogram/dispatcher/dispatcher.py:407> exception=OperationalError('no such table: User')>
Traceback (most recent call last):
  File "/home/ivan/past_dev/Project/Telegram_bot/telegram_finance/venv/lib64/python3.10/site-packages/peewee.py", line 3237, in execute_sql
    cursor.execute(sql, params or ())
sqlite3.OperationalError: no such table: User

During handling of the above exception, another exception occurred:

Traceback (most recent call last):
  File "/home/ivan/past_dev/Project/Telegram_bot/telegram_finance/venv/lib64/python3.10/site-packages/aiogram/dispatcher/dispatcher.py", line 415, in _process_polling_updates
    for responses in itertools.chain.from_iterable(await self.process_updates(updates, fast)):
  File "/home/ivan/past_dev/Project/Telegram_bot/telegram_finance/venv/lib64/python3.10/site-packages/aiogram/dispatcher/dispatcher.py", line 235, in process_updates
    return await asyncio.gather(*tasks)
  File "/home/ivan/past_dev/Project/Telegram_bot/telegram_finance/venv/lib64/python3.10/site-packages/aiogram/dispatcher/handler.py", line 117, in notify
    response = await handler_obj.handler(*args, **partial_data)
  File "/home/ivan/past_dev/Project/Telegram_bot/telegram_finance/venv/lib64/python3.10/site-packages/aiogram/dispatcher/dispatcher.py", line 256, in process_update
    return await self.message_handlers.notify(update.message)
  File "/home/ivan/past_dev/Project/Telegram_bot/telegram_finance/venv/lib64/python3.10/site-packages/aiogram/dispatcher/handler.py", line 117, in notify
    response = await handler_obj.handler(*args, **partial_data)
  File "/home/ivan/past_dev/Project/Telegram_bot/telegram_finance/server.py", line 20, in cmd_start
    User(id_telegram=data["id_telegram"], name=data["name"], last_name=data["last_name"]).save()
  File "/home/ivan/past_dev/Project/Telegram_bot/telegram_finance/venv/lib64/python3.10/site-packages/peewee.py", line 6742, in save
    pk = self.insert(**field_dict).execute()
  File "/home/ivan/past_dev/Project/Telegram_bot/telegram_finance/venv/lib64/python3.10/site-packages/peewee.py", line 1962, in inner
    return method(self, database, *args, **kwargs)
  File "/home/ivan/past_dev/Project/Telegram_bot/telegram_finance/venv/lib64/python3.10/site-packages/peewee.py", line 2033, in execute
    return self._execute(database)
  File "/home/ivan/past_dev/Project/Telegram_bot/telegram_finance/venv/lib64/python3.10/site-packages/peewee.py", line 2838, in _execute
    return super(Insert, self)._execute(database)
  File "/home/ivan/past_dev/Project/Telegram_bot/telegram_finance/venv/lib64/python3.10/site-packages/peewee.py", line 2551, in _execute
    cursor = database.execute(self)
  File "/home/ivan/past_dev/Project/Telegram_bot/telegram_finance/venv/lib64/python3.10/site-packages/peewee.py", line 3250, in execute
    return self.execute_sql(sql, params, commit=commit)
  File "/home/ivan/past_dev/Project/Telegram_bot/telegram_finance/venv/lib64/python3.10/site-packages/peewee.py", line 3234, in execute_sql
    with __exception_wrapper__:
  File "/home/ivan/past_dev/Project/Telegram_bot/telegram_finance/venv/lib64/python3.10/site-packages/peewee.py", line 3010, in __exit__
    reraise(new_type, new_type(exc_value, *exc_args), traceback)
  File "/home/ivan/past_dev/Project/Telegram_bot/telegram_finance/venv/lib64/python3.10/site-packages/peewee.py", line 192, in reraise
    raise value.with_traceback(tb)
  File "/home/ivan/past_dev/Project/Telegram_bot/telegram_finance/venv/lib64/python3.10/site-packages/peewee.py", line 3237, in execute_sql
    cursor.execute(sql, params or ())
peewee.OperationalError: no such table: User
WARNING:aiogram.dispatcher.dispatcher:Polling is stopped.
INFO:aiogram.dispatcher.dispatcher:Stop polling...
ERROR:asyncio:Unclosed client session
client_session: <aiohttp.client.ClientSession object at 0x7f9b49e25d20>
INFO:aiogram.dispatcher.dispatcher:Start polling.
INFO:root:{"message_id": 20, "from": {"id": 1211431388, "is_bot": false, "first_name": "Иван", "last_name": "Книженцев", "username": "IKnigencev", "language_code": "ru"}, "chat": {"id": 1211431388, "first_name": "Иван", "last_name": "Книженцев", "username": "IKnigencev", "type": "private"}, "date": 1675106609, "text": "/start", "entities": [{"type": "bot_command", "offset": 0, "length": 6}]}
ERROR:asyncio:Task exception was never retrieved
future: <Task finished name='Task-8' coro=<Dispatcher._process_polling_updates() done, defined at /home/ivan/past_dev/Project/Telegram_bot/telegram_finance/venv/lib64/python3.10/site-packages/aiogram/dispatcher/dispatcher.py:407> exception=OperationalError('no such table: user')>
Traceback (most recent call last):
  File "/home/ivan/past_dev/Project/Telegram_bot/telegram_finance/venv/lib64/python3.10/site-packages/peewee.py", line 3237, in execute_sql
    cursor.execute(sql, params or ())
sqlite3.OperationalError: no such table: user

During handling of the above exception, another exception occurred:

Traceback (most recent call last):
  File "/home/ivan/past_dev/Project/Telegram_bot/telegram_finance/venv/lib64/python3.10/site-packages/aiogram/dispatcher/dispatcher.py", line 415, in _process_polling_updates
    for responses in itertools.chain.from_iterable(await self.process_updates(updates, fast)):
  File "/home/ivan/past_dev/Project/Telegram_bot/telegram_finance/venv/lib64/python3.10/site-packages/aiogram/dispatcher/dispatcher.py", line 235, in process_updates
    return await asyncio.gather(*tasks)
  File "/home/ivan/past_dev/Project/Telegram_bot/telegram_finance/venv/lib64/python3.10/site-packages/aiogram/dispatcher/handler.py", line 117, in notify
    response = await handler_obj.handler(*args, **partial_data)
  File "/home/ivan/past_dev/Project/Telegram_bot/telegram_finance/venv/lib64/python3.10/site-packages/aiogram/dispatcher/dispatcher.py", line 256, in process_update
    return await self.message_handlers.notify(update.message)
  File "/home/ivan/past_dev/Project/Telegram_bot/telegram_finance/venv/lib64/python3.10/site-packages/aiogram/dispatcher/handler.py", line 117, in notify
    response = await handler_obj.handler(*args, **partial_data)
  File "/home/ivan/past_dev/Project/Telegram_bot/telegram_finance/server.py", line 20, in cmd_start
    User(id_telegram=data["id_telegram"], name=data["name"], last_name=data["last_name"]).save()
  File "/home/ivan/past_dev/Project/Telegram_bot/telegram_finance/venv/lib64/python3.10/site-packages/peewee.py", line 6742, in save
    pk = self.insert(**field_dict).execute()
  File "/home/ivan/past_dev/Project/Telegram_bot/telegram_finance/venv/lib64/python3.10/site-packages/peewee.py", line 1962, in inner
    return method(self, database, *args, **kwargs)
  File "/home/ivan/past_dev/Project/Telegram_bot/telegram_finance/venv/lib64/python3.10/site-packages/peewee.py", line 2033, in execute
    return self._execute(database)
  File "/home/ivan/past_dev/Project/Telegram_bot/telegram_finance/venv/lib64/python3.10/site-packages/peewee.py", line 2838, in _execute
    return super(Insert, self)._execute(database)
  File "/home/ivan/past_dev/Project/Telegram_bot/telegram_finance/venv/lib64/python3.10/site-packages/peewee.py", line 2551, in _execute
    cursor = database.execute(self)
  File "/home/ivan/past_dev/Project/Telegram_bot/telegram_finance/venv/lib64/python3.10/site-packages/peewee.py", line 3250, in execute
    return self.execute_sql(sql, params, commit=commit)
  File "/home/ivan/past_dev/Project/Telegram_bot/telegram_finance/venv/lib64/python3.10/site-packages/peewee.py", line 3234, in execute_sql
    with __exception_wrapper__:
  File "/home/ivan/past_dev/Project/Telegram_bot/telegram_finance/venv/lib64/python3.10/site-packages/peewee.py", line 3010, in __exit__
    reraise(new_type, new_type(exc_value, *exc_args), traceback)
  File "/home/ivan/past_dev/Project/Telegram_bot/telegram_finance/venv/lib64/python3.10/site-packages/peewee.py", line 192, in reraise
    raise value.with_traceback(tb)
  File "/home/ivan/past_dev/Project/Telegram_bot/telegram_finance/venv/lib64/python3.10/site-packages/peewee.py", line 3237, in execute_sql
    cursor.execute(sql, params or ())
peewee.OperationalError: no such table: user
WARNING:aiogram.dispatcher.dispatcher:Polling is stopped.
INFO:aiogram.dispatcher.dispatcher:Stop polling...
ERROR:asyncio:Unclosed client session
client_session: <aiohttp.client.ClientSession object at 0x7ff5e7101e40>
INFO:aiogram.dispatcher.dispatcher:Start polling.
INFO:root:{"message_id": 21, "from": {"id": 1211431388, "is_bot": false, "first_name": "Иван", "last_name": "Книженцев", "username": "IKnigencev", "language_code": "ru"}, "chat": {"id": 1211431388, "first_name": "Иван", "last_name": "Книженцев", "username": "IKnigencev", "type": "private"}, "date": 1675106741, "text": "/start", "entities": [{"type": "bot_command", "offset": 0, "length": 6}]}
ERROR:asyncio:Task exception was never retrieved
future: <Task finished name='Task-8' coro=<Dispatcher._process_polling_updates() done, defined at /home/ivan/past_dev/Project/Telegram_bot/telegram_finance/venv/lib64/python3.10/site-packages/aiogram/dispatcher/dispatcher.py:407> exception=OperationalError('no such table: user')>
Traceback (most recent call last):
  File "/home/ivan/past_dev/Project/Telegram_bot/telegram_finance/venv/lib64/python3.10/site-packages/peewee.py", line 3237, in execute_sql
    cursor.execute(sql, params or ())
sqlite3.OperationalError: no such table: user

During handling of the above exception, another exception occurred:

Traceback (most recent call last):
  File "/home/ivan/past_dev/Project/Telegram_bot/telegram_finance/venv/lib64/python3.10/site-packages/aiogram/dispatcher/dispatcher.py", line 415, in _process_polling_updates
    for responses in itertools.chain.from_iterable(await self.process_updates(updates, fast)):
  File "/home/ivan/past_dev/Project/Telegram_bot/telegram_finance/venv/lib64/python3.10/site-packages/aiogram/dispatcher/dispatcher.py", line 235, in process_updates
    return await asyncio.gather(*tasks)
  File "/home/ivan/past_dev/Project/Telegram_bot/telegram_finance/venv/lib64/python3.10/site-packages/aiogram/dispatcher/handler.py", line 117, in notify
    response = await handler_obj.handler(*args, **partial_data)
  File "/home/ivan/past_dev/Project/Telegram_bot/telegram_finance/venv/lib64/python3.10/site-packages/aiogram/dispatcher/dispatcher.py", line 256, in process_update
    return await self.message_handlers.notify(update.message)
  File "/home/ivan/past_dev/Project/Telegram_bot/telegram_finance/venv/lib64/python3.10/site-packages/aiogram/dispatcher/handler.py", line 117, in notify
    response = await handler_obj.handler(*args, **partial_data)
  File "/home/ivan/past_dev/Project/Telegram_bot/telegram_finance/server.py", line 20, in cmd_start
    User(id_telegram=data["id_telegram"], name=data["name"], last_name=data["last_name"]).save()
  File "/home/ivan/past_dev/Project/Telegram_bot/telegram_finance/venv/lib64/python3.10/site-packages/peewee.py", line 6742, in save
    pk = self.insert(**field_dict).execute()
  File "/home/ivan/past_dev/Project/Telegram_bot/telegram_finance/venv/lib64/python3.10/site-packages/peewee.py", line 1962, in inner
    return method(self, database, *args, **kwargs)
  File "/home/ivan/past_dev/Project/Telegram_bot/telegram_finance/venv/lib64/python3.10/site-packages/peewee.py", line 2033, in execute
    return self._execute(database)
  File "/home/ivan/past_dev/Project/Telegram_bot/telegram_finance/venv/lib64/python3.10/site-packages/peewee.py", line 2838, in _execute
    return super(Insert, self)._execute(database)
  File "/home/ivan/past_dev/Project/Telegram_bot/telegram_finance/venv/lib64/python3.10/site-packages/peewee.py", line 2551, in _execute
    cursor = database.execute(self)
  File "/home/ivan/past_dev/Project/Telegram_bot/telegram_finance/venv/lib64/python3.10/site-packages/peewee.py", line 3250, in execute
    return self.execute_sql(sql, params, commit=commit)
  File "/home/ivan/past_dev/Project/Telegram_bot/telegram_finance/venv/lib64/python3.10/site-packages/peewee.py", line 3234, in execute_sql
    with __exception_wrapper__:
  File "/home/ivan/past_dev/Project/Telegram_bot/telegram_finance/venv/lib64/python3.10/site-packages/peewee.py", line 3010, in __exit__
    reraise(new_type, new_type(exc_value, *exc_args), traceback)
  File "/home/ivan/past_dev/Project/Telegram_bot/telegram_finance/venv/lib64/python3.10/site-packages/peewee.py", line 192, in reraise
    raise value.with_traceback(tb)
  File "/home/ivan/past_dev/Project/Telegram_bot/telegram_finance/venv/lib64/python3.10/site-packages/peewee.py", line 3237, in execute_sql
    cursor.execute(sql, params or ())
peewee.OperationalError: no such table: user
WARNING:aiogram.dispatcher.dispatcher:Polling is stopped.
INFO:aiogram.dispatcher.dispatcher:Stop polling...
ERROR:asyncio:Unclosed client session
client_session: <aiohttp.client.ClientSession object at 0x7f6707415ea0>
INFO:aiogram.dispatcher.dispatcher:Start polling.
INFO:root:{"message_id": 22, "from": {"id": 1211431388, "is_bot": false, "first_name": "Иван", "last_name": "Книженцев", "username": "IKnigencev", "language_code": "ru"}, "chat": {"id": 1211431388, "first_name": "Иван", "last_name": "Книженцев", "username": "IKnigencev", "type": "private"}, "date": 1675106783, "text": "/start", "entities": [{"type": "bot_command", "offset": 0, "length": 6}]}
WARNING:aiogram.dispatcher.dispatcher:Polling is stopped.
INFO:aiogram.dispatcher.dispatcher:Stop polling...
ERROR:asyncio:Unclosed client session
client_session: <aiohttp.client.ClientSession object at 0x7f8942d860e0>
INFO:aiogram.dispatcher.dispatcher:Start polling.
INFO:root:SELECT "t1"."id", "t1"."id_telegram", "t1"."name", "t1"."last_name" FROM "user" AS "t1"
WARNING:aiogram.dispatcher.dispatcher:Polling is stopped.
INFO:aiogram.dispatcher.dispatcher:Stop polling...
ERROR:asyncio:Unclosed client session
client_session: <aiohttp.client.ClientSession object at 0x7f5c44501e10>
INFO:aiogram.dispatcher.dispatcher:Start polling.
INFO:root:('SELECT "t1"."id", "t1"."id_telegram", "t1"."name", "t1"."last_name" FROM "user" AS "t1"', [])
WARNING:aiogram.dispatcher.dispatcher:Polling is stopped.
INFO:aiogram.dispatcher.dispatcher:Stop polling...
ERROR:asyncio:Unclosed client session
client_session: <aiohttp.client.ClientSession object at 0x7f4e9c151f00>
INFO:aiogram.dispatcher.dispatcher:Start polling.
INFO:root:('SELECT "t1"."id", "t1"."id_telegram", "t1"."name", "t1"."last_name" FROM "user" AS "t1"', [])
WARNING:aiogram.dispatcher.dispatcher:Polling is stopped.
INFO:aiogram.dispatcher.dispatcher:Stop polling...
ERROR:asyncio:Unclosed client session
client_session: <aiohttp.client.ClientSession object at 0x7fb0018ddc30>
INFO:aiogram.dispatcher.dispatcher:Start polling.
ERROR:asyncio:Task exception was never retrieved
future: <Task finished name='Task-6' coro=<Dispatcher._process_polling_updates() done, defined at /home/ivan/past_dev/Project/Telegram_bot/telegram_finance/venv/lib64/python3.10/site-packages/aiogram/dispatcher/dispatcher.py:407> exception=IntegrityError('UNIQUE constraint failed: user.id_telegram')>
Traceback (most recent call last):
  File "/home/ivan/past_dev/Project/Telegram_bot/telegram_finance/venv/lib64/python3.10/site-packages/peewee.py", line 3237, in execute_sql
    cursor.execute(sql, params or ())
sqlite3.IntegrityError: UNIQUE constraint failed: user.id_telegram

During handling of the above exception, another exception occurred:

Traceback (most recent call last):
  File "/home/ivan/past_dev/Project/Telegram_bot/telegram_finance/venv/lib64/python3.10/site-packages/aiogram/dispatcher/dispatcher.py", line 415, in _process_polling_updates
    for responses in itertools.chain.from_iterable(await self.process_updates(updates, fast)):
  File "/home/ivan/past_dev/Project/Telegram_bot/telegram_finance/venv/lib64/python3.10/site-packages/aiogram/dispatcher/dispatcher.py", line 235, in process_updates
    return await asyncio.gather(*tasks)
  File "/home/ivan/past_dev/Project/Telegram_bot/telegram_finance/venv/lib64/python3.10/site-packages/aiogram/dispatcher/handler.py", line 117, in notify
    response = await handler_obj.handler(*args, **partial_data)
  File "/home/ivan/past_dev/Project/Telegram_bot/telegram_finance/venv/lib64/python3.10/site-packages/aiogram/dispatcher/dispatcher.py", line 256, in process_update
    return await self.message_handlers.notify(update.message)
  File "/home/ivan/past_dev/Project/Telegram_bot/telegram_finance/venv/lib64/python3.10/site-packages/aiogram/dispatcher/handler.py", line 117, in notify
    response = await handler_obj.handler(*args, **partial_data)
  File "/home/ivan/past_dev/Project/Telegram_bot/telegram_finance/server.py", line 19, in cmd_start
    User.create(id_telegram=data["id_telegram"], name=data["name"], last_name=data["last_name"]).save()
  File "/home/ivan/past_dev/Project/Telegram_bot/telegram_finance/venv/lib64/python3.10/site-packages/peewee.py", line 6532, in create
    inst.save(force_insert=True)
  File "/home/ivan/past_dev/Project/Telegram_bot/telegram_finance/venv/lib64/python3.10/site-packages/peewee.py", line 6742, in save
    pk = self.insert(**field_dict).execute()
  File "/home/ivan/past_dev/Project/Telegram_bot/telegram_finance/venv/lib64/python3.10/site-packages/peewee.py", line 1962, in inner
    return method(self, database, *args, **kwargs)
  File "/home/ivan/past_dev/Project/Telegram_bot/telegram_finance/venv/lib64/python3.10/site-packages/peewee.py", line 2033, in execute
    return self._execute(database)
  File "/home/ivan/past_dev/Project/Telegram_bot/telegram_finance/venv/lib64/python3.10/site-packages/peewee.py", line 2838, in _execute
    return super(Insert, self)._execute(database)
  File "/home/ivan/past_dev/Project/Telegram_bot/telegram_finance/venv/lib64/python3.10/site-packages/peewee.py", line 2551, in _execute
    cursor = database.execute(self)
  File "/home/ivan/past_dev/Project/Telegram_bot/telegram_finance/venv/lib64/python3.10/site-packages/peewee.py", line 3250, in execute
    return self.execute_sql(sql, params, commit=commit)
  File "/home/ivan/past_dev/Project/Telegram_bot/telegram_finance/venv/lib64/python3.10/site-packages/peewee.py", line 3234, in execute_sql
    with __exception_wrapper__:
  File "/home/ivan/past_dev/Project/Telegram_bot/telegram_finance/venv/lib64/python3.10/site-packages/peewee.py", line 3010, in __exit__
    reraise(new_type, new_type(exc_value, *exc_args), traceback)
  File "/home/ivan/past_dev/Project/Telegram_bot/telegram_finance/venv/lib64/python3.10/site-packages/peewee.py", line 192, in reraise
    raise value.with_traceback(tb)
  File "/home/ivan/past_dev/Project/Telegram_bot/telegram_finance/venv/lib64/python3.10/site-packages/peewee.py", line 3237, in execute_sql
    cursor.execute(sql, params or ())
peewee.IntegrityError: UNIQUE constraint failed: user.id_telegram
WARNING:aiogram.dispatcher.dispatcher:Polling is stopped.
INFO:aiogram.dispatcher.dispatcher:Stop polling...
ERROR:asyncio:Unclosed client session
client_session: <aiohttp.client.ClientSession object at 0x7fcd1430de10>
INFO:aiogram.dispatcher.dispatcher:Start polling.
ERROR:asyncio:Task exception was never retrieved
future: <Task finished name='Task-6' coro=<Dispatcher._process_polling_updates() done, defined at /home/ivan/past_dev/Project/Telegram_bot/telegram_finance/venv/lib64/python3.10/site-packages/aiogram/dispatcher/dispatcher.py:407> exception=AttributeError("'tuple' object has no attribute 'save'")>
Traceback (most recent call last):
  File "/home/ivan/past_dev/Project/Telegram_bot/telegram_finance/venv/lib64/python3.10/site-packages/aiogram/dispatcher/dispatcher.py", line 415, in _process_polling_updates
    for responses in itertools.chain.from_iterable(await self.process_updates(updates, fast)):
  File "/home/ivan/past_dev/Project/Telegram_bot/telegram_finance/venv/lib64/python3.10/site-packages/aiogram/dispatcher/dispatcher.py", line 235, in process_updates
    return await asyncio.gather(*tasks)
  File "/home/ivan/past_dev/Project/Telegram_bot/telegram_finance/venv/lib64/python3.10/site-packages/aiogram/dispatcher/handler.py", line 117, in notify
    response = await handler_obj.handler(*args, **partial_data)
  File "/home/ivan/past_dev/Project/Telegram_bot/telegram_finance/venv/lib64/python3.10/site-packages/aiogram/dispatcher/dispatcher.py", line 256, in process_update
    return await self.message_handlers.notify(update.message)
  File "/home/ivan/past_dev/Project/Telegram_bot/telegram_finance/venv/lib64/python3.10/site-packages/aiogram/dispatcher/handler.py", line 117, in notify
    response = await handler_obj.handler(*args, **partial_data)
  File "/home/ivan/past_dev/Project/Telegram_bot/telegram_finance/server.py", line 19, in cmd_start
    User.get_or_create(id_telegram=data["id_telegram"], name=data["name"], last_name=data["last_name"]).save()
AttributeError: 'tuple' object has no attribute 'save'
WARNING:aiogram.dispatcher.dispatcher:Polling is stopped.
INFO:aiogram.dispatcher.dispatcher:Stop polling...
ERROR:asyncio:Unclosed client session
client_session: <aiohttp.client.ClientSession object at 0x7f429b70dd20>
INFO:aiogram.dispatcher.dispatcher:Start polling.
INFO:root:(<User: Иван>, False)
INFO:root:('SELECT "t1"."id", "t1"."id_telegram", "t1"."name", "t1"."last_name" FROM "user" AS "t1"', [])
WARNING:aiogram.dispatcher.dispatcher:Polling is stopped.
INFO:aiogram.dispatcher.dispatcher:Stop polling...
ERROR:asyncio:Unclosed client session
client_session: <aiohttp.client.ClientSession object at 0x7f96676a1e40>
INFO:aiogram.dispatcher.dispatcher:Start polling.
INFO:root:(<User: Иван>, False)
INFO:root:Иван
WARNING:aiogram.dispatcher.dispatcher:Polling is stopped.
INFO:aiogram.dispatcher.dispatcher:Stop polling...
ERROR:asyncio:Unclosed client session
client_session: <aiohttp.client.ClientSession object at 0x7fd3947c5ed0>
INFO:aiogram.dispatcher.dispatcher:Start polling.
WARNING:aiogram.dispatcher.dispatcher:Polling is stopped.
INFO:aiogram.dispatcher.dispatcher:Stop polling...
ERROR:asyncio:Unclosed client session
client_session: <aiohttp.client.ClientSession object at 0x7f274cca5e40>
ERROR:asyncio:Unclosed connector
connections: ['[(<aiohttp.client_proto.ResponseHandler object at 0x7f274ca751e0>, 9613.268903746)]']
connector: <aiohttp.connector.TCPConnector object at 0x7f274cca42e0>
INFO:aiogram.dispatcher.dispatcher:Start polling.
